[2023-03-22T14:45:53.135+0000] {taskinstance.py:1084} INFO - Dependencies all met for dep_context=non-requeueable deps ti=<TaskInstance: asndjfsdf_v02.extract scheduled__2023-03-21T00:00:00+00:00 [queued]>
[2023-03-22T14:45:53.161+0000] {taskinstance.py:1084} INFO - Dependencies all met for dep_context=requeueable deps ti=<TaskInstance: asndjfsdf_v02.extract scheduled__2023-03-21T00:00:00+00:00 [queued]>
[2023-03-22T14:45:53.161+0000] {taskinstance.py:1282} INFO - 
--------------------------------------------------------------------------------
[2023-03-22T14:45:53.162+0000] {taskinstance.py:1283} INFO - Starting attempt 4 of 6
[2023-03-22T14:45:53.162+0000] {taskinstance.py:1284} INFO - 
--------------------------------------------------------------------------------
[2023-03-22T14:45:53.207+0000] {taskinstance.py:1303} INFO - Executing <Task(PythonOperator): extract> on 2023-03-21 00:00:00+00:00
[2023-03-22T14:45:53.217+0000] {standard_task_runner.py:55} INFO - Started process 7922 to run task
[2023-03-22T14:45:53.225+0000] {standard_task_runner.py:82} INFO - Running: ['***', 'tasks', 'run', 'asndjfsdf_v02', 'extract', 'scheduled__2023-03-21T00:00:00+00:00', '--job-id', '410', '--raw', '--subdir', 'DAGS_FOLDER/ashfjasdg.py', '--cfg-path', '/tmp/tmpe7xd1kq9']
[2023-03-22T14:45:53.228+0000] {standard_task_runner.py:83} INFO - Job 410: Subtask extract
[2023-03-22T14:45:53.341+0000] {task_command.py:388} INFO - Running <TaskInstance: asndjfsdf_v02.extract scheduled__2023-03-21T00:00:00+00:00 [running]> on host 7a7b82ed390a
[2023-03-22T14:45:53.480+0000] {taskinstance.py:1511} INFO - Exporting the following env vars:
AIRFLOW_CTX_DAG_OWNER=Mr.Phi
AIRFLOW_CTX_DAG_ID=asndjfsdf_v02
AIRFLOW_CTX_TASK_ID=extract
AIRFLOW_CTX_EXECUTION_DATE=2023-03-21T00:00:00+00:00
AIRFLOW_CTX_TRY_NUMBER=4
AIRFLOW_CTX_DAG_RUN_ID=scheduled__2023-03-21T00:00:00+00:00
[2023-03-22T14:46:27.757+0000] {taskinstance.py:1775} ERROR - Task failed with exception
Traceback (most recent call last):
  File "/home/airflow/.local/lib/python3.7/site-packages/sqlalchemy/engine/base.py", line 3361, in _wrap_pool_connect
    return fn()
  File "/home/airflow/.local/lib/python3.7/site-packages/sqlalchemy/pool/base.py", line 327, in connect
    return _ConnectionFairy._checkout(self)
  File "/home/airflow/.local/lib/python3.7/site-packages/sqlalchemy/pool/base.py", line 894, in _checkout
    fairy = _ConnectionRecord.checkout(pool)
  File "/home/airflow/.local/lib/python3.7/site-packages/sqlalchemy/pool/base.py", line 493, in checkout
    rec = pool._do_get()
  File "/home/airflow/.local/lib/python3.7/site-packages/sqlalchemy/pool/impl.py", line 146, in _do_get
    self._dec_overflow()
  File "/home/airflow/.local/lib/python3.7/site-packages/sqlalchemy/util/langhelpers.py", line 72, in __exit__
    with_traceback=exc_tb,
  File "/home/airflow/.local/lib/python3.7/site-packages/sqlalchemy/util/compat.py", line 211, in raise_
    raise exception
  File "/home/airflow/.local/lib/python3.7/site-packages/sqlalchemy/pool/impl.py", line 143, in _do_get
    return self._create_connection()
  File "/home/airflow/.local/lib/python3.7/site-packages/sqlalchemy/pool/base.py", line 273, in _create_connection
    return _ConnectionRecord(self)
  File "/home/airflow/.local/lib/python3.7/site-packages/sqlalchemy/pool/base.py", line 388, in __init__
    self.__connect()
  File "/home/airflow/.local/lib/python3.7/site-packages/sqlalchemy/pool/base.py", line 691, in __connect
    pool.logger.debug("Error on connect(): %s", e)
  File "/home/airflow/.local/lib/python3.7/site-packages/sqlalchemy/util/langhelpers.py", line 72, in __exit__
    with_traceback=exc_tb,
  File "/home/airflow/.local/lib/python3.7/site-packages/sqlalchemy/util/compat.py", line 211, in raise_
    raise exception
  File "/home/airflow/.local/lib/python3.7/site-packages/sqlalchemy/pool/base.py", line 686, in __connect
    self.dbapi_connection = connection = pool._invoke_creator(self)
  File "/home/airflow/.local/lib/python3.7/site-packages/sqlalchemy/engine/create.py", line 578, in connect
    return dialect.connect(*cargs, **cparams)
  File "/home/airflow/.local/lib/python3.7/site-packages/sqlalchemy/engine/default.py", line 598, in connect
    return self.dbapi.connect(*cargs, **cparams)
pyodbc.OperationalError: ('HYT00', '[HYT00] [Microsoft][ODBC Driver 17 for SQL Server]Login timeout expired (0) (SQLDriverConnect)')

The above exception was the direct cause of the following exception:

Traceback (most recent call last):
  File "/home/airflow/.local/lib/python3.7/site-packages/airflow/operators/python.py", line 175, in execute
    return_value = self.execute_callable()
  File "/home/airflow/.local/lib/python3.7/site-packages/airflow/operators/python.py", line 192, in execute_callable
    return self.python_callable(*self.op_args, **self.op_kwargs)
  File "/opt/airflow/dags/ashfjasdg.py", line 32, in extract
    df = pd.read_sql_table('jobs_v04', engine)
  File "/home/airflow/.local/lib/python3.7/site-packages/pandas/io/sql.py", line 320, in read_sql_table
    meta.reflect(only=[table_name], views=True)
  File "/home/airflow/.local/lib/python3.7/site-packages/sqlalchemy/sql/schema.py", line 4842, in reflect
    with inspection.inspect(bind)._inspection_context() as insp:
  File "/home/airflow/.local/lib/python3.7/site-packages/sqlalchemy/inspection.py", line 64, in inspect
    ret = reg(subject)
  File "/home/airflow/.local/lib/python3.7/site-packages/sqlalchemy/engine/reflection.py", line 182, in _engine_insp
    return Inspector._construct(Inspector._init_engine, bind)
  File "/home/airflow/.local/lib/python3.7/site-packages/sqlalchemy/engine/reflection.py", line 117, in _construct
    init(self, bind)
  File "/home/airflow/.local/lib/python3.7/site-packages/sqlalchemy/engine/reflection.py", line 128, in _init_engine
    engine.connect().close()
  File "/home/airflow/.local/lib/python3.7/site-packages/sqlalchemy/engine/base.py", line 3315, in connect
    return self._connection_cls(self, close_with_result=close_with_result)
  File "/home/airflow/.local/lib/python3.7/site-packages/sqlalchemy/engine/base.py", line 96, in __init__
    else engine.raw_connection()
  File "/home/airflow/.local/lib/python3.7/site-packages/sqlalchemy/engine/base.py", line 3394, in raw_connection
    return self._wrap_pool_connect(self.pool.connect, _connection)
  File "/home/airflow/.local/lib/python3.7/site-packages/sqlalchemy/engine/base.py", line 3365, in _wrap_pool_connect
    e, dialect, self
  File "/home/airflow/.local/lib/python3.7/site-packages/sqlalchemy/engine/base.py", line 2199, in _handle_dbapi_exception_noconnection
    sqlalchemy_exception, with_traceback=exc_info[2], from_=e
  File "/home/airflow/.local/lib/python3.7/site-packages/sqlalchemy/util/compat.py", line 211, in raise_
    raise exception
  File "/home/airflow/.local/lib/python3.7/site-packages/sqlalchemy/engine/base.py", line 3361, in _wrap_pool_connect
    return fn()
  File "/home/airflow/.local/lib/python3.7/site-packages/sqlalchemy/pool/base.py", line 327, in connect
    return _ConnectionFairy._checkout(self)
  File "/home/airflow/.local/lib/python3.7/site-packages/sqlalchemy/pool/base.py", line 894, in _checkout
    fairy = _ConnectionRecord.checkout(pool)
  File "/home/airflow/.local/lib/python3.7/site-packages/sqlalchemy/pool/base.py", line 493, in checkout
    rec = pool._do_get()
  File "/home/airflow/.local/lib/python3.7/site-packages/sqlalchemy/pool/impl.py", line 146, in _do_get
    self._dec_overflow()
  File "/home/airflow/.local/lib/python3.7/site-packages/sqlalchemy/util/langhelpers.py", line 72, in __exit__
    with_traceback=exc_tb,
  File "/home/airflow/.local/lib/python3.7/site-packages/sqlalchemy/util/compat.py", line 211, in raise_
    raise exception
  File "/home/airflow/.local/lib/python3.7/site-packages/sqlalchemy/pool/impl.py", line 143, in _do_get
    return self._create_connection()
  File "/home/airflow/.local/lib/python3.7/site-packages/sqlalchemy/pool/base.py", line 273, in _create_connection
    return _ConnectionRecord(self)
  File "/home/airflow/.local/lib/python3.7/site-packages/sqlalchemy/pool/base.py", line 388, in __init__
    self.__connect()
  File "/home/airflow/.local/lib/python3.7/site-packages/sqlalchemy/pool/base.py", line 691, in __connect
    pool.logger.debug("Error on connect(): %s", e)
  File "/home/airflow/.local/lib/python3.7/site-packages/sqlalchemy/util/langhelpers.py", line 72, in __exit__
    with_traceback=exc_tb,
  File "/home/airflow/.local/lib/python3.7/site-packages/sqlalchemy/util/compat.py", line 211, in raise_
    raise exception
  File "/home/airflow/.local/lib/python3.7/site-packages/sqlalchemy/pool/base.py", line 686, in __connect
    self.dbapi_connection = connection = pool._invoke_creator(self)
  File "/home/airflow/.local/lib/python3.7/site-packages/sqlalchemy/engine/create.py", line 578, in connect
    return dialect.connect(*cargs, **cparams)
  File "/home/airflow/.local/lib/python3.7/site-packages/sqlalchemy/engine/default.py", line 598, in connect
    return self.dbapi.connect(*cargs, **cparams)
sqlalchemy.exc.OperationalError: (pyodbc.OperationalError) ('HYT00', '[HYT00] [Microsoft][ODBC Driver 17 for SQL Server]Login timeout expired (0) (SQLDriverConnect)')
(Background on this error at: https://sqlalche.me/e/14/e3q8)
[2023-03-22T14:46:27.822+0000] {taskinstance.py:1326} INFO - Marking task as UP_FOR_RETRY. dag_id=asndjfsdf_v02, task_id=extract, execution_date=20230321T000000, start_date=20230322T144553, end_date=20230322T144627
[2023-03-22T14:46:27.845+0000] {standard_task_runner.py:105} ERROR - Failed to execute job 410 for task extract ((pyodbc.OperationalError) ('HYT00', '[HYT00] [Microsoft][ODBC Driver 17 for SQL Server]Login timeout expired (0) (SQLDriverConnect)')
(Background on this error at: https://sqlalche.me/e/14/e3q8); 7922)
[2023-03-22T14:46:27.898+0000] {local_task_job.py:212} INFO - Task exited with return code 1
[2023-03-22T14:46:27.922+0000] {taskinstance.py:2585} INFO - 0 downstream tasks scheduled from follow-on schedule check
